Workbook
Name BenA_DiaChi: DATA!$C$18
Name BenA_NT1: DATA!$C$21
Name BenA_NT1_CV: DATA!$C$22
Name BenA_NT2: DATA!$C$23
Name BenA_NT2_CV: DATA!$C$24
Name BenA_PL: DATA!$C$19
Name BenA_PL_CV: DATA!$C$20
Name BenA_Ten: DATA!$C$17
Name BenB_DiaChi: DATA!$C$27
Name BenB_NT1: DATA!$C$30
Name BenB_NT1_CV: DATA!$C$31
Name BenB_NT2: DATA!$C$32
Name BenB_NT2_CV: DATA!$C$33
Name BenB_PL: DATA!$C$28
Name BenB_PL_CV: DATA!$C$29
Name BenB_Ten: DATA!$C$26
Name COCQ: DATA!$C$36
Name DiaDiem: DATA!$C$8
Name DuAn: DATA!$C$5
Name GoiThau: DATA!$C$6
Name HangMuc: DATA!$C$7
Name MaDA: DATA!$C$9
Name NgayBBVT: DATA!$C$15
Name NgayHD: DATA!$C$12
Name NgayPL: DATA!$C$14
Name NhaSX: DATA!$C$35
Name SoHD: DATA!$C$11
Name SoPL: DATA!$C$13

Sheet DATA
B1: BẢNG DỮ LIỆU DÙNG CHUNG - HỒ SƠ NGHIỆM THU THANG MÁY P3
B2: Cập nhật giá trị tại cột "Giá trị" (ô nền vàng); toàn bộ các sheet Phiếu yêu cầu và Biên bản sẽ tự động cập nhật theo.
B4: THÔNG TIN DỰ ÁN
B5: Dự án
B6: Gói thầu
B7: Hạng mục
B8: Địa điểm
B9: Mã hồ sơ (dự án)
B10: HỢP ĐỒNG
B11: Số hợp đồng
B12: Ngày ký hợp đồng
B13: Số phụ lục hợp đồng
... B36: Giấy xuất xưởng, số lô (CO, CQ)

Sheet DanhMuc
A1: DANH MỤC HỒ SƠ NGHIỆM THU THANG MÁY P3
A2: Nhập Ngày phát hành / Giờ bắt đầu / Giờ kết thúc / Ngày nghiệm thu tại các ô nền vàng (ngày dạng dd/mm/yyyy, ví dụ 05/02/2026; giờ dạng 08h30). Tên tài liệu sửa tại cột C; Số hiệu tự động theo Mã hồ sơ ở sheet DATA. Toàn bộ các sheet Phiếu yêu cầu và Biên bản sẽ tự cập nhật theo.
A4: STT | B4: Loại | C4: Tên tài liệu | D4: Số hiệu | E4: Ngày phát hành | F4: Giờ bắt đầu | G4: Giờ kết thúc | H4: Ngày nghiệm thu | I4: Sheet
A5: 1 | B5: Phiếu YC | C5: Phiếu yêu cầu nghiệm thu lắp đặt tĩnh thiết bị thang máy | D5: ="1/TM/PYCNTLĐT-TB/"&MaDA&"-P3" | I5: PYC1_LapDatTinh
B6: Biên bản | C6: Biên bản nghiệm thu lắp đặt tĩnh thang máy P3 | D6: ="1/TM/BBNLT/"&MaDA&"-P3" | I6: BB1_LapDatTinh
A7: 2 | B7: Phiếu YC | C7: Phiếu yêu cầu nghiệm thu chạy thử đơn động không tải thang máy | D7: ="2/TM/PYCNTĐĐKT-TB/"&MaDA&"-P3" | I7: PYC2_DonDongKhongTai
B8: Biên bản | C8: Biên bản nghiệm thu chạy thử đơn động không tải thang máy P3 | D8: ="2/TM/BBNCTDDKT/"&MaDA&"-P3" | I8: BB2_DonDongKhongTai
A9: 3 | B9: Phiếu YC | C9: Phiếu yêu cầu nghiệm thu chạy thử đơn động có tải thang máy | D9: ="3/TM/PYCNTĐĐCT-TB/"&MaDA&"-P3" | I9: PYC3_DonDongCoTai
B10: Biên bản | C10: Biên bản nghiệm thu chạy thử đơn động có tải thang máy P3 | D10: ="3/TM/BBNCTDDCT/"&MaDA&"-P3" | I10: BB3_DonDongCoTai
A11: 4 | B11: Phiếu YC | C11: Phiếu yêu cầu nghiệm thu chạy thử liên động không tải thang máy | D11: ="4/TM/PYCNTLĐKT-TB/"&MaDA&"-P3" | I11: PYC4_LienDongKhongTai
B12: Biên bản | C12: Biên bản nghiệm thu chạy thử liên động không tải thang máy P3 | D12: ="4/TM/BBNCTLDKT/"&MaDA&"-P3" | I12: BB4_LienDongKhongTai
A13: 5 | B13: Phiếu YC | C13: Phiếu yêu cầu nghiệm thu chạy thử liên động có tải thang máy | D13: ="5/TM/PYCNTLĐCT-TB/"&MaDA&"-P3" | I13: PYC5_LienDongCoTai
B14: Biên bản | C14: Biên bản nghiệm thu chạy thử liên động có tải thang máy P3 | D14: ="5/TM/BBNCTLDCT/"&MaDA&"-P3" | I14: BB5_LienDongCoTai
A15: 6 | B15: Phiếu YC | C15: Phiếu yêu cầu nghiệm thu hoàn thành hạng mục thang máy | D15: ="6/TM/PYCNTHTHM-TB/"&MaDA&"-P3" | I15: PYC6_HoanThanhHangMuc
B16: Biên bản | C16: Biên bản nghiệm thu hoàn thành hạng mục đưa vào sử dụng | D16: ="6/TM/BBNTHM/"&MaDA&"-P3" | I16: BB6_HoanThanhHangMuc
A17: 7 | B17: Bàn giao | C17: Biên bản bàn giao thang máy | D17: ="7/TM/BBBG/"&MaDA&"-P3" | I17: BBG_BanGiao

Sheet PYC1_LapDatTinh
A1: CỘNG HÒA XÃ HỘI CHỦ NGHĨA VIỆT NAM
A2: Độc lập - Tự do - Hạnh phúc
A3: --------o0o--------
A4: ="Hà Nội, "&IF(LEN(DanhMuc!$E$5)=10,"ngày "&LEFT(DanhMuc!$E$5,2)&" tháng "&MID(DanhMuc!$E$5,4,2)&" năm "&RIGHT(DanhMuc!$E$5,4),"ngày …... tháng …... năm 2026")&"."
A5: PHIẾU YÊU CẦU NGHIỆM THU
A6: =UPPER(SUBSTITUTE(DanhMuc!$C$5,"Phiếu yêu cầu nghiệm thu ",""))
A7: ="SỐ: "&DanhMuc!$D$5
A8: ="Dự án : "&DuAn
A9: ="Gói thầu : "&GoiThau
A10: ="Hạng mục : "&HangMuc
A11: ="Địa điểm : "&DiaDiem
A12: ="Bên A (Bên Mua) : "&BenA_Ten&" - "&BenA_DiaChi
A13: ="Bên B (Bên Bán) : "&BenB_Ten&" - "&BenB_DiaChi
A14: Đối tượng yêu cầu nghiệm thu:
A15: Thang máy P3 và các thiết bị, phụ kiện đi kèm
A16: ="Hợp đồng mua bán số "&SoHD&" ký ngày "&NgayHD&" và "&"Phụ lục Hợp đồng số "&SoPL&" ký ngày "&NgayPL&"."
A17: ="Biên bản phê duyệt vật liệu, sản phẩm xây dựng/Biên bản phê duyệt thiết bị số: 1/TM/BBNTVL-TB/"&MaDA&" ngày "&NgayBBVT&"."
A18: Khối lượng đề nghị nghiệm thu:
A19: TT | B19: Loại vật liệu, sản phẩm | D19: Số lượng | E19: Quy cách | F19: Chủng loại | H19: Giấy xuất xưởng, số lô (CO, CQ) | J19: Nhà sản xuất
A20: 1 | B20: Thang máy P3 và các thiết bị, phụ kiện đi kèm | D20: 1 | E20: Bộ | F20: Thang máy chở khách, PCCC, có Phòng máy | H20: =COCQ | J20: =NhaSX
A21: Đại diện Bên B (Bên Bán):
A22: ="Ông: "&BenB_PL&" Chức vụ: "&BenB_PL_CV&" Chữ ký: ….........................."
A23: Sau khi kiểm tra hồ sơ và quy trình lắp đặt, chạy thử; đối chiếu với bản vẽ thiết kế và các tiêu chuẩn được áp dụng; đối chiếu Hợp đồng, hồ sơ thiết kế, chỉ dẫn kỹ thuật và các quy chuẩn, tiêu chuẩn được áp dụng, chúng tôi đã hoàn thành nghiệm thu nội bộ và khẳng định rằng: Chất lượng Công việc lắp đặt đảm bảo các yêu cầu kỹ thuật và đủ điều kiện nghiệm thu.
A24: ="Đề nghị Bên A (Bên Mua) - "&BenA_Ten&" tổ chức nghiệm thu:"
A25: ="Thời gian nghiệm thu: "&IF(DanhMuc!$F$5="","10h00",DanhMuc!$F$5)&" "&IF(LEN(DanhMuc!$H$5)=10,"Ngày "&LEFT(DanhMuc!$H$5,2)&" Tháng "&MID(DanhMuc!$H$5,4,2)&" Năm "&RIGHT(DanhMuc!$H$5,4),"Ngày …. Tháng …... Năm ….....")
A26: Tài liệu kèm theo:
A27: - Biên bản giao hàng;
A28: - Chứng chỉ chất lượng sản phẩm;
A29: - Kết quả thí nghiệm vật liệu;
A30: ="- Dự thảo Biên bản nghiệm thu lắp đặt tĩnh số "&DanhMuc!$D$6&" kèm Bảng kiểm tra (Checklist)."
A31: ="ĐẠI DIỆN BÊN A ("&UPPER(BenA_Ten)&")" | D31: Đã nhận Phiếu yêu cầu lúc 10h20 Ngày …. Tháng …... Năm …..... | H31: Người nhận

Sheet BB1_LapDatTinh
A2: CỘNG HÒA XÃ HỘI CHỦ NGHĨA VIỆT NAM
A3: Độc lập - Tự do - Hạnh phúc
A4: --------o0o--------
A5: ="Hà Nội, "&IF(LEN(DanhMuc!$E$6)=10,"ngày "&LEFT(DanhMuc!$E$6,2)&" tháng "&MID(DanhMuc!$E$6,4,2)&" năm "&RIGHT(DanhMuc!$E$6,4),"ngày …... tháng …... năm 2026")
A6: =UPPER(DanhMuc!$C$6)
A7: ="SỐ: "&DanhMuc!$D$6
A8: ="Dự án: "&DuAn
A9: ="Gói thầu: "&GoiThau
A10: ="Hạng mục: "&HangMuc
A11: ="Địa điểm: "&DiaDiem
A12: 1. Đối tượng nghiệm thu:
A13: Thang máy P3 (thang máy chở người/PCCC có phòng máy, nhãn hiệu Schindler) và toàn bộ thiết bị, phụ kiện đi kèm - Nghiệm thu lắp đặt tĩnh.
A14: 2. Thành phần nghiệm thu:
A15: ="- Đại diện Bên A (Bên Mua): "&BenA_Ten
A16: =" Ông/Bà: "&IF(BenA_NT1="","…......................................",BenA_NT1)&" Chức vụ: "&IF(BenA_NT1_CV="","…....................",BenA_NT1_CV)
A17: =" Ông/Bà: "&IF(BenA_NT2="","…......................................",BenA_NT2)&" Chức vụ: "&IF(BenA_NT2_CV="","…....................",BenA_NT2_CV)
A18: ="- Đại diện Bên B (Bên Bán): "&BenB_Ten
A19: =" Ông/Bà: "&IF(BenB_NT1="","…......................................",BenB_NT1)&" Chức vụ: "&IF(BenB_NT1_CV="","…....................",BenB_NT1_CV)
A20: =" Ông/Bà: "&IF(BenB_NT2="","…......................................",BenB_NT2)&" Chức vụ: "&IF(BenB_NT2_CV="","…....................",BenB_NT2_CV)
A21: 3. Thời gian và địa điểm nghiệm thu:
A22: ="- Bắt đầu: "&IF(DanhMuc!$F$6="","…....... giờ …....... phút",DanhMuc!$F$6)&", "&IF(LEN(DanhMuc!$H$6)=10,"ngày "&LEFT(DanhMuc!$H$6,2)&" tháng "&MID(DanhMuc!$H$6,4,2)&" năm "&RIGHT(DanhMuc!$H$6,4),"ngày …....... tháng …....... năm 2026")
A23: ="- Kết thúc: "&IF(DanhMuc!$G$6="","…....... giờ …....... phút",DanhMuc!$G$6)&", "&IF(LEN(DanhMuc!$H$6)=10,"ngày "&LEFT(DanhMuc!$H$6,2)&" tháng "&MID(DanhMuc!$H$6,4,2)&" năm "&RIGHT(DanhMuc!$H$6,4),"ngày …....... tháng …....... năm 2026")
A24: - Tại: Công trường Tòa nhà Trung tâm Điều hành, Khu Trung tâm ĐHQG Hà Nội, xã Hòa Lạc, Hà Nội
A25: 4. Căn cứ nghiệm thu:
A26: a) Tài liệu pháp lý và hợp đồng:
A27: ="- Hợp đồng mua bán số "&SoHD&" ký ngày "&NgayHD&" giữa "&BenA_Ten&" (Bên A) và "&BenB_Ten&" (Bên B)."
A28: ="- "&"Phụ lục Hợp đồng số "&SoPL&" ký ngày "&NgayPL&" của Hợp đồng số "&SoHD&"."
A29: - Hồ sơ thiết kế, bản vẽ thi công thang máy được hai Bên phê duyệt.
A30: - Biên bản phê duyệt vật liệu/thiết bị số: ….......
A31: ="- Biên bản nghiệm thu vật tư thiết bị số: 1/TM/BBNTVL-TB/"&MaDA&" ngày "&NgayBBVT&"."
A32: b) Quy chuẩn, tiêu chuẩn áp dụng:
A33: - Nghị định 06/2021/NĐ-CP: Quản lý chất lượng và bảo trì công trình xây dựng;
A34: - Thông tư 10/2021/TT-BXD hướng dẫn thi hành Nghị định 06/2021/NĐ-CP;
A35: - QCVN 02:2019/BLĐTBXH: Quy chuẩn kỹ thuật quốc gia về an toàn lao động đối với thang máy;
A36: - TCVN 6396-20:2017 (EN 81-20:2014): Yêu cầu an toàn về cấu tạo và lắp đặt thang máy chở người;
A37: - TCVN 6396-72:2010 (EN 81-72:2003): Thang máy chữa cháy - yêu cầu an toàn;
A38: - Và các tiêu chuẩn liên quan khác.
A39: c) Tài liệu kỹ thuật:
A40: - Nhật ký thi công, nhật ký giám sát và các văn bản liên quan đến đối tượng nghiệm thu.
A41: - Catalogue kỹ thuật và chứng chỉ chất lượng của nhà sản xuất Schindler.
...

Sheet PYC2_DonDongKhongTai
A1: CỘNG HÒA XÃ HỘI CHỦ NGHĨA VIỆT NAM
A2: Độc lập - Tự do - Hạnh phúc
A3: --------o0o--------
A4: ="Hà Nội, "&IF(LEN(DanhMuc!$E$7)=10,"ngày "&LEFT(DanhMuc!$E$7,2)&" tháng "&MID(DanhMuc!$E$7,4,2)&" năm "&RIGHT(DanhMuc!$E$7,4),"ngày …... tháng …... năm 2026")&"."
A5: PHIẾU YÊU CẦU NGHIỆM THU
A6: =UPPER(SUBSTITUTE(DanhMuc!$C$7,"Phiếu yêu cầu nghiệm thu ",""))
A7: ="SỐ: "&DanhMuc!$D$7
A8: ="Dự án : "&DuAn
A9: ="Gói thầu : "&GoiThau
A10: ="Hạng mục : "&HangMuc
A11: ="Địa điểm : "&DiaDiem
A12: ="Bên A (Bên Mua) : "&BenA_Ten&" - "&BenA_DiaChi
A13: ="Bên B (Bên Bán) : "&BenB_Ten&" - "&BenB_DiaChi
A14: Đối tượng yêu cầu nghiệm thu:
A15: Thang máy P3 và các thiết bị, phụ kiện đi kèm
A16: ="Hợp đồng mua bán số "&SoHD&" ký ngày "&NgayHD&" và "&"Phụ lục Hợp đồng số "&SoPL&" ký ngày "&NgayPL&"."
A17: ="Biên bản phê duyệt vật liệu, sản phẩm xây dựng/Biên bản phê duyệt thiết bị số: 1/TM/BBNTVL-TB/"&MaDA&" ngày "&NgayBBVT&"."
A18: Khối lượng đề nghị nghiệm thu:
A19: TT | B19: Loại vật liệu, sản phẩm | D19: Số lượng | E19: Quy cách | F19: Chủng loại | H19: Giấy xuất xưởng, số lô (CO, CQ) | J19: Nhà sản xuất
A20: 1 | B20: Thang máy P3 và các thiết bị, phụ kiện đi kèm | D20: 1 | E20: Bộ | F20: Thang máy chở khách, PCCC, có Phòng máy | H20: =COCQ | J20: =NhaSX
A21: Đại diện Bên B (Bên Bán):
A22: ="Ông: "&BenB_PL&" Chức vụ: "&BenB_PL_CV&" Chữ ký: ….........................."
A23: Sau khi kiểm tra hồ sơ và quy trình lắp đặt, chạy thử; đối chiếu với bản vẽ thiết kế và các tiêu chuẩn được áp dụng; đối chiếu Hợp đồng, hồ sơ thiết kế, chỉ dẫn kỹ thuật và các quy chuẩn, tiêu chuẩn được áp dụng, chúng tôi đã hoàn thành nghiệm thu nội bộ và khẳng định rằng: Chất lượng Công việc chạy thử đảm bảo các yêu cầu kỹ thuật và đủ điều kiện nghiệm thu.
A24: ="Đề nghị Bên A (Bên Mua) - "&BenA_Ten&" tổ chức nghiệm thu:"
A25: ="Thời gian nghiệm thu: "&IF(DanhMuc!$F$7="","10h00",DanhMuc!$F$7)&" "&IF(LEN(DanhMuc!$H$7)=10,"Ngày "&LEFT(DanhMuc!$H$7,2)&" Tháng "&MID(DanhMuc!$H$7,4,2)&" Năm "&RIGHT(DanhMuc!$H$7,4),"Ngày …. Tháng …... Năm ….....")
A26: Tài liệu kèm theo:
A27: - Biên bản giao hàng;
A28: - Chứng chỉ chất lượng sản phẩm;
A29: - Kết quả thí nghiệm vật liệu;
A30: ="- Dự thảo Biên bản nghiệm thu chạy thử đơn động không tải số "&DanhMuc!$D$8&" kèm Bảng kiểm tra (Checklist)."
A31: ="ĐẠI DIỆN BÊN A ("&UPPER(BenA_Ten)&")" | D31: Đã nhận Phiếu yêu cầu lúc 10h20 Ngày …. Tháng …... Năm …..... | H31: Người nhận

Sheet BB2_DonDongKhongTai
A2: CỘNG HÒA XÃ HỘI CHỦ NGHĨA VIỆT NAM
A3: Độc lập - Tự do - Hạnh phúc
A4: --------o0o--------
A5: ="Hà Nội, "&IF(LEN(DanhMuc!$E$8)=10,"ngày "&LEFT(DanhMuc!$E$8,2)&" tháng "&MID(DanhMuc!$E$8,4,2)&" năm "&RIGHT(DanhMuc!$E$8,4),"ngày …... tháng …... năm 2026")
A6: =UPPER(DanhMuc!$C$8)
A7: THANG MÁY P3
A8: ="SỐ: "&DanhMuc!$D$8
A9: ="Dự án: "&DuAn
A10: ="Gói thầu: "&GoiThau
A11: ="Hạng mục: "&HangMuc
A12: ="Địa điểm: "&DiaDiem
A13: 1. Đối tượng nghiệm thu:
A14: Thang máy P3 (thang máy chở người/PCCC có phòng máy, Schindler) - Chạy thử đơn động không tải.
A15: 2. Thành phần nghiệm thu:
A16: ="- Đại diện Bên A (Bên Mua): "&BenA_Ten
A17: =" Ông/Bà: "&IF(BenA_NT1="","…......................................",BenA_NT1)&" Chức vụ: "&IF(BenA_NT1_CV="","…....................",BenA_NT1_CV)
A18: =" Ông/Bà: "&IF(BenA_NT2="","…......................................",BenA_NT2)&" Chức vụ: "&IF(BenA_NT2_CV="","…....................",BenA_NT2_CV)
A19: ="- Đại diện Bên B (Bên Bán): "&BenB_Ten
A20: =" Ông/Bà: "&IF(BenB_NT1="","…......................................",BenB_NT1)&" Chức vụ: "&IF(BenB_NT1_CV="","…....................",BenB_NT1_CV)
A21: =" Ông/Bà: "&IF(BenB_NT2="","…......................................",BenB_NT2)&" Chức vụ: "&IF(BenB_NT2_CV="","…....................",BenB_NT2_CV)
A22: 3. Thời gian và địa điểm nghiệm thu:
A23: ="- Bắt đầu: "&IF(DanhMuc!$F$8="","…....... giờ …....... phút",DanhMuc!$F$8)&", "&IF(LEN(DanhMuc!$H$8)=10,"ngày "&LEFT(DanhMuc!$H$8,2)&" tháng "&MID(DanhMuc!$H$8,4,2)&" năm "&RIGHT(DanhMuc!$H$8,4),"ngày …....... tháng …....... năm 2026")
A24: ="- Kết thúc: "&IF(DanhMuc!$G$8="","…....... giờ …....... phút",DanhMuc!$G$8)&", "&IF(LEN(DanhMuc!$H$8)=10,"ngày "&LEFT(DanhMuc!$H$8,2)&" tháng "&MID(DanhMuc!$H$8,4,2)&" năm "&RIGHT(DanhMuc!$H$8,4),"ngày …....... tháng …....... năm 2026")
A25: - Tại: Công trường Tòa nhà Trung tâm Điều hành, Khu Trung tâm ĐHQG Hà Nội, xã Hòa Lạc, Hà Nội
A26: 4. Căn cứ nghiệm thu:
A27: a) Tài liệu pháp lý và hợp đồng:
A28: ="- Hợp đồng mua bán số "&SoHD&" ký ngày "&NgayHD&" giữa "&BenA_Ten&" (Bên A) và "&BenB_Ten&" (Bên B)."
A29: ="- "&"Phụ lục Hợp đồng số "&SoPL&" ký ngày "&NgayPL&" của Hợp đồng số "&SoHD&"."
A30: - Hồ sơ thiết kế, bản vẽ thi công thang máy được hai Bên phê duyệt.
A31: ="- Biên bản nghiệm thu vật tư thiết bị số: 1/TM/BBNTVL-TB/"&MaDA&" ngày "&NgayBBVT&"."
A32: ="- Biên bản nghiệm thu lắp đặt tĩnh số: "&DanhMuc!$D$6
A33: b) Quy chuẩn, tiêu chuẩn áp dụng:
A34: - Nghị định 06/2021/NĐ-CP: Quản lý chất lượng và bảo trì công trình xây dựng;
A35: - Thông tư 10/2021/TT-BXD hướng dẫn thi hành Nghị định 06/2021/NĐ-CP;
A36: - QCVN 02:2019/BLĐTBXH: Quy chuẩn kỹ thuật quốc gia về an toàn lao động đối với thang máy;
A37: - TCVN 6396-20:2017 (EN 81-20:2014): Yêu cầu an toàn về cấu tạo và lắp đặt thang máy chở người;
A38: - TCVN 6396-72:2010 (EN 81-72:2003): Thang máy chữa cháy - yêu cầu an toàn;
A39: - Và các tiêu chuẩn liên quan khác.
A40: c) Tài liệu kỹ thuật:
A41: - Nhật ký thi công, nhật ký giám sát và các văn bản liên quan đến đối tượng nghiệm thu.
...

Sheet PYC3_DonDongCoTai
A1: CỘNG HÒA XÃ HỘI CHỦ NGHĨA VIỆT NAM
A2: Độc lập - Tự do - Hạnh phúc
A3: --------o0o--------
A4: ="Hà Nội, "&IF(LEN(DanhMuc!$E$9)=10,"ngày "&LEFT(DanhMuc!$E$9,2)&" tháng "&MID(DanhMuc!$E$9,4,2)&" năm "&RIGHT(DanhMuc!$E$9,4),"ngày …... tháng …... năm 2026")&"."
A5: PHIẾU YÊU CẦU NGHIỆM THU
A6: =UPPER(SUBSTITUTE(DanhMuc!$C$9,"Phiếu yêu cầu nghiệm thu ",""))
A7: ="SỐ: "&DanhMuc!$D$9
A8: ="Dự án : "&DuAn
A9: ="Gói thầu : "&GoiThau
A10: ="Hạng mục : "&HangMuc
A11: ="Địa điểm : "&DiaDiem
A12: ="Bên A (Bên Mua) : "&BenA_Ten&" - "&BenA_DiaChi
A13: ="Bên B (Bên Bán) : "&BenB_Ten&" - "&BenB_DiaChi
A14: Đối tượng yêu cầu nghiệm thu:
A15: Thang máy P3 và các thiết bị, phụ kiện đi kèm
A16: ="Hợp đồng mua bán số "&SoHD&" ký ngày "&NgayHD&" và "&"Phụ lục Hợp đồng số "&SoPL&" ký ngày "&NgayPL&"."
A17: ="Biên bản phê duyệt vật liệu, sản phẩm xây dựng/Biên bản phê duyệt thiết bị số: 1/TM/BBNTVL-TB/"&MaDA&" ngày "&NgayBBVT&"."
A18: Khối lượng đề nghị nghiệm thu:
A19: TT | B19: Loại vật liệu, sản phẩm | D19: Số lượng | E19: Quy cách | F19: Chủng loại | H19: Giấy xuất xưởng, số lô (CO, CQ) | J19: Nhà sản xuất
A20: 1 | B20: Thang máy P3 và các thiết bị, phụ kiện đi kèm | D20: 1 | E20: Bộ | F20: Thang máy chở khách, PCCC, có Phòng máy | H20: =COCQ | J20: =NhaSX
A21: Đại diện Bên B (Bên Bán):
A22: ="Ông: "&BenB_PL&" Chức vụ: "&BenB_PL_CV&" Chữ ký: ….........................."
A23: Sau khi kiểm tra hồ sơ và quy trình lắp đặt, chạy thử; đối chiếu với bản vẽ thiết kế và các tiêu chuẩn được áp dụng; đối chiếu Hợp đồng, hồ sơ thiết kế, chỉ dẫn kỹ thuật và các quy chuẩn, tiêu chuẩn được áp dụng, chúng tôi đã hoàn thành nghiệm thu nội bộ và khẳng định rằng: Chất lượng Công việc chạy thử đảm bảo các yêu cầu kỹ thuật và đủ điều kiện nghiệm thu.
A24: ="Đề nghị Bên A (Bên Mua) - "&BenA_Ten&" tổ chức nghiệm thu:"
A25: ="Thời gian nghiệm thu: "&IF(DanhMuc!$F$9="","10h00",DanhMuc!$F$9)&" "&IF(LEN(DanhMuc!$H$9)=10,"Ngày "&LEFT(DanhMuc!$H$9,2)&" Tháng "&MID(DanhMuc!$H$9,4,2)&" Năm "&RIGHT(DanhMuc!$H$9,4),"Ngày …. Tháng …... Năm ….....")
A26: Tài liệu kèm theo:
A27: - Biên bản giao hàng;
A28: - Chứng chỉ chất lượng sản phẩm;
A29: - Kết quả thí nghiệm vật liệu;
A30: ="- Dự thảo Biên bản nghiệm thu chạy thử đơn động có tải số "&DanhMuc!$D$10&" kèm Bảng kiểm tra (Checklist)."
A31: ="ĐẠI DIỆN BÊN A ("&UPPER(BenA_Ten)&")" | D31: Đã nhận Phiếu yêu cầu lúc 10h20 Ngày …. Tháng …... Năm …..... | H31: Người nhận

Sheet BB3_DonDongCoTai
A2: CỘNG HÒA XÃ HỘI CHỦ NGHĨA VIỆT NAM
A3: Độc lập - Tự do - Hạnh phúc
A4: --------o0o--------
A5: ="Hà Nội, "&IF(LEN(DanhMuc!$E$10)=10,"ngày "&LEFT(DanhMuc!$E$10,2)&" tháng "&MID(DanhMuc!$E$10,4,2)&" năm "&RIGHT(DanhMuc!$E$10,4),"ngày …... tháng …... năm 2026")
A6: =UPPER(DanhMuc!$C$10)
A7: THANG MÁY P3
A8: ="SỐ: "&DanhMuc!$D$10
A9: ="Dự án: "&DuAn
A10: ="Gói thầu: "&GoiThau
A11: ="Hạng mục: "&HangMuc
A12: ="Địa điểm: "&DiaDiem
A13: 1. Đối tượng nghiệm thu:
A14: Thang máy P3 (thang máy chở người/PCCC có phòng máy, Schindler) - Chạy thử đơn động có tải (25%, 50%, 75%, 100%, 110% tải định mức).
A15: 2. Thành phần nghiệm thu:
A16: ="- Đại diện Bên A (Bên Mua): "&BenA_Ten
A17: =" Ông/Bà: "&IF(BenA_NT1="","…......................................",BenA_NT1)&" Chức vụ: "&IF(BenA_NT1_CV="","…....................",BenA_NT1_CV)
A18: =" Ông/Bà: "&IF(BenA_NT2="","…......................................",BenA_NT2)&" Chức vụ: "&IF(BenA_NT2_CV="","…....................",BenA_NT2_CV)
A19: ="- Đại diện Bên B (Bên Bán): "&BenB_Ten
A20: =" Ông/Bà: "&IF(BenB_NT1="","…......................................",BenB_NT1)&" Chức vụ: "&IF(BenB_NT1_CV="","…....................",BenB_NT1_CV)
A21: =" Ông/Bà: "&IF(BenB_NT2="","…......................................",BenB_NT2)&" Chức vụ: "&IF(BenB_NT2_CV="","…....................",BenB_NT2_CV)
A22: 3. Thời gian và địa điểm nghiệm thu:
A23: ="- Bắt đầu: "&IF(DanhMuc!$F$10="","…....... giờ …....... phút",DanhMuc!$F$10)&", "&IF(LEN(DanhMuc!$H$10)=10,"ngày "&LEFT(DanhMuc!$H$10,2)&" tháng "&MID(DanhMuc!$H$10,4,2)&" năm "&RIGHT(DanhMuc!$H$10,4),"ngày …....... tháng …....... năm 2026")
A24: ="- Kết thúc: "&IF(DanhMuc!$G$10="","…....... giờ …....... phút",DanhMuc!$G$10)&", "&IF(LEN(DanhMuc!$H$10)=10,"ngày "&LEFT(DanhMuc!$H$10,2)&" tháng "&MID(DanhMuc!$H$10,4,2)&" năm "&RIGHT(DanhMuc!$H$10,4),"ngày …....... tháng …....... năm 2026")
A25: - Tại: Công trường Tòa nhà Trung tâm Điều hành, Khu Trung tâm ĐHQG Hà Nội, xã Hòa Lạc, Hà Nội
A26: 4. Căn cứ nghiệm thu:
A27: a) Tài liệu pháp lý và hợp đồng:
A28: ="- Hợp đồng mua bán số "&SoHD&" ký ngày "&NgayHD&" giữa "&BenA_Ten&" (Bên A) và "&BenB_Ten&" (Bên B)."
A29: ="- "&"Phụ lục Hợp đồng số "&SoPL&" ký ngày "&NgayPL&" của Hợp đồng số "&SoHD&"."
A30: - Hồ sơ thiết kế, bản vẽ thi công thang máy được hai Bên phê duyệt.
A31: ="- Biên bản nghiệm thu vật tư thiết bị số: 1/TM/BBNTVL-TB/"&MaDA&" ngày "&NgayBBVT&"."
A32: ="- Biên bản nghiệm thu đơn động không tải số: "&DanhMuc!$D$8
A33: b) Quy chuẩn, tiêu chuẩn áp dụng:
A34: - Nghị định 06/2021/NĐ-CP: Quản lý chất lượng và bảo trì công trình xây dựng;
A35: - Thông tư 10/2021/TT-BXD hướng dẫn thi hành Nghị định 06/2021/NĐ-CP;
A36: - QCVN 02:2019/BLĐTBXH: Quy chuẩn kỹ thuật quốc gia về an toàn lao động đối với thang máy;
A37: - TCVN 6396-20:2017 (EN 81-20:2014): Yêu cầu an toàn về cấu tạo và lắp đặt thang máy chở người;
A38: - TCVN 6396-72:2010 (EN 81-72:2003): Thang máy chữa cháy - yêu cầu an toàn;
A39: - Và các tiêu chuẩn liên quan khác.
A40: c) Tài liệu kỹ thuật:
A41: - Nhật ký thi công, nhật ký giám sát và các văn bản liên quan đến đối tượng nghiệm thu.
...

Sheet PYC4_LienDongKhongTai
A1: CỘNG HÒA XÃ HỘI CHỦ NGHĨA VIỆT NAM
A2: Độc lập - Tự do - Hạnh phúc
A3: --------o0o--------
A4: ="Hà Nội, "&IF(LEN(DanhMuc!$E$11)=10,"ngày "&LEFT(DanhMuc!$E$11,2)&" tháng "&MID(DanhMuc!$E$11,4,2)&" năm "&RIGHT(DanhMuc!$E$11,4),"ngày …... tháng …... năm 2026")&"."
A5: PHIẾU YÊU CẦU NGHIỆM THU
A6: =UPPER(SUBSTITUTE(DanhMuc!$C$11,"Phiếu yêu cầu nghiệm thu ",""))
A7: ="SỐ: "&DanhMuc!$D$11
A8: ="Dự án : "&DuAn
A9: ="Gói thầu : "&GoiThau
A10: ="Hạng mục : "&HangMuc
A11: ="Địa điểm : "&DiaDiem
A12: ="Bên A (Bên Mua) : "&BenA_Ten&" - "&BenA_DiaChi
A13: ="Bên B (Bên Bán) : "&BenB_Ten&" - "&BenB_DiaChi
A14: Đối tượng yêu cầu nghiệm thu:
A15: Thang máy P3 và các thiết bị, phụ kiện đi kèm
A16: ="Hợp đồng mua bán số "&SoHD&" ký ngày "&NgayHD&" và "&"Phụ lục Hợp đồng số "&SoPL&" ký ngày "&NgayPL&"."
A17: ="Biên bản phê duyệt vật liệu, sản phẩm xây dựng/Biên bản phê duyệt thiết bị số: 1/TM/BBNTVL-TB/"&MaDA&" ngày "&NgayBBVT&"."
A18: Khối lượng đề nghị nghiệm thu:
A19: TT | B19: Loại vật liệu, sản phẩm | D19: Số lượng | E19: Quy cách | F19: Chủng loại | H19: Giấy xuất xưởng, số lô (CO, CQ) | J19: Nhà sản xuất
A20: 1 | B20: Thang máy P3 và các thiết bị, phụ kiện đi kèm | D20: 1 | E20: Bộ | F20: Thang máy chở khách, PCCC, có Phòng máy | H20: =COCQ | J20: =NhaSX
A21: Đại diện Bên B (Bên Bán):
A22: ="Ông: "&BenB_PL&" Chức vụ: "&BenB_PL_CV&" Chữ ký: ….........................."
A23: Sau khi kiểm tra hồ sơ và quy trình lắp đặt, chạy thử; đối chiếu với bản vẽ thiết kế và các tiêu chuẩn được áp dụng; đối chiếu Hợp đồng, hồ sơ thiết kế, chỉ dẫn kỹ thuật và các quy chuẩn, tiêu chuẩn được áp dụng, chúng tôi đã hoàn thành nghiệm thu nội bộ và khẳng định rằng: Chất lượng Công việc chạy thử đảm bảo các yêu cầu kỹ thuật và đủ điều kiện nghiệm thu.
A24: ="Đề nghị Bên A (Bên Mua) - "&BenA_Ten&" tổ chức nghiệm thu:"
A25: ="Thời gian nghiệm thu: "&IF(DanhMuc!$F$11="","10h00",DanhMuc!$F$11)&" "&IF(LEN(DanhMuc!$H$11)=10,"Ngày "&LEFT(DanhMuc!$H$11,2)&" Tháng "&MID(DanhMuc!$H$11,4,2)&" Năm "&RIGHT(DanhMuc!$H$11,4),"Ngày …. Tháng …... Năm ….....")
A26: Tài liệu kèm theo:
A27: - Biên bản giao hàng;
A28: - Chứng chỉ chất lượng sản phẩm;
A29: - Kết quả thí nghiệm vật liệu;
A30: ="- Dự thảo Biên bản nghiệm thu chạy thử liên động không tải số "&DanhMuc!$D$12&" kèm Bảng kiểm tra (Checklist)."
A31: ="ĐẠI DIỆN BÊN A ("&UPPER(BenA_Ten)&")" | D31: Đã nhận Phiếu yêu cầu lúc 10h20 Ngày …. Tháng …... Năm …..... | H31: Người nhận

Sheet BB4_LienDongKhongTai
A2: CỘNG HÒA XÃ HỘI CHỦ NGHĨA VIỆT NAM
A3: Độc lập - Tự do - Hạnh phúc
A4: --------o0o--------
A5: ="Hà Nội, "&IF(LEN(DanhMuc!$E$12)=10,"ngày "&LEFT(DanhMuc!$E$12,2)&" tháng "&MID(DanhMuc!$E$12,4,2)&" năm "&RIGHT(DanhMuc!$E$12,4),"ngày …... tháng …... năm 2026")
A6: =UPPER(DanhMuc!$C$12)
A7: ="SỐ: "&DanhMuc!$D$12
A8: ="Dự án: "&DuAn
A9: ="Gói thầu: "&GoiThau
A10: ="Hạng mục: "&HangMuc
A11: ="Địa điểm: "&DiaDiem
A12: 1. Đối tượng nghiệm thu:
A13: Thang máy P3 (thang máy chở người/PCCC có phòng máy, Schindler) - Chạy thử liên động không tải với các hệ thống liên quan của tòa nhà (báo cháy/PCCC, BMS, nguồn điện, liên lạc khẩn cấp).
A14: 2. Thành phần nghiệm thu:
A15: ="- Đại diện Bên A (Bên Mua): "&BenA_Ten
A16: =" Ông/Bà: "&IF(BenA_NT1="","…......................................",BenA_NT1)&" Chức vụ: "&IF(BenA_NT1_CV="","…....................",BenA_NT1_CV)
A17: =" Ông/Bà: "&IF(BenA_NT2="","…......................................",BenA_NT2)&" Chức vụ: "&IF(BenA_NT2_CV="","…....................",BenA_NT2_CV)
A18: ="- Đại diện Bên B (Bên Bán): "&BenB_Ten
A19: =" Ông/Bà: "&IF(BenB_NT1="","…......................................",BenB_NT1)&" Chức vụ: "&IF(BenB_NT1_CV="","…....................",BenB_NT1_CV)
A20: =" Ông/Bà: "&IF(BenB_NT2="","…......................................",BenB_NT2)&" Chức vụ: "&IF(BenB_NT2_CV="","…....................",BenB_NT2_CV)
A21: 3. Thời gian và địa điểm nghiệm thu:
A22: ="- Bắt đầu: "&IF(DanhMuc!$F$12="","…....... giờ …....... phút",DanhMuc!$F$12)&", "&IF(LEN(DanhMuc!$H$12)=10,"ngày "&LEFT(DanhMuc!$H$12,2)&" tháng "&MID(DanhMuc!$H$12,4,2)&" năm "&RIGHT(DanhMuc!$H$12,4),"ngày …....... tháng …....... năm 2026")
A23: ="- Kết thúc: "&IF(DanhMuc!$G$12="","…....... giờ …....... phút",DanhMuc!$G$12)&", "&IF(LEN(DanhMuc!$H$12)=10,"ngày "&LEFT(DanhMuc!$H$12,2)&" tháng "&MID(DanhMuc!$H$12,4,2)&" năm "&RIGHT(DanhMuc!$H$12,4),"ngày …....... tháng …....... năm 2026")
A24: - Tại: Công trường Tòa nhà Trung tâm Điều hành, Khu Trung tâm ĐHQG Hà Nội, xã Hòa Lạc, Hà Nội
A25: 4. Căn cứ nghiệm thu:
A26: a) Tài liệu pháp lý và hợp đồng:
A27: ="- Hợp đồng mua bán số "&SoHD&" ký ngày "&NgayHD&" giữa "&BenA_Ten&" (Bên A) và "&BenB_Ten&" (Bên B)."
A28: ="- "&"Phụ lục Hợp đồng số "&SoPL&" ký ngày "&NgayPL&" của Hợp đồng số "&SoHD&"."
A29: - Hồ sơ thiết kế, bản vẽ thi công thang máy được hai Bên phê duyệt.
A30: - Biên bản phê duyệt vật liệu/thiết bị số: ….......
A31: ="- Biên bản nghiệm thu vật tư thiết bị số: 1/TM/BBNTVL-TB/"&MaDA&" ngày "&NgayBBVT&"."
A32: ="- Biên bản nghiệm thu đơn động có tải P3: "&DanhMuc!$D$10
A33: b) Quy chuẩn, tiêu chuẩn áp dụng:
A34: - Nghị định 06/2021/NĐ-CP: Quản lý chất lượng và bảo trì công trình xây dựng;
A35: - Thông tư 10/2021/TT-BXD hướng dẫn thi hành Nghị định 06/2021/NĐ-CP;
A36: - QCVN 02:2019/BLĐTBXH: Quy chuẩn kỹ thuật quốc gia về an toàn lao động đối với thang máy;
A37: - TCVN 6396-20:2017 (EN 81-20:2014): Yêu cầu an toàn về cấu tạo và lắp đặt thang máy chở người;
A38: - TCVN 6396-72:2010 (EN 81-72:2003): Thang máy chữa cháy - yêu cầu an toàn;
A39: - TCVN 170:2007: Kết cấu thép - Gia công, lắp ráp và nghiệm thu;
A40: - Và các tiêu chuẩn liên quan khác.
A41: c) Tài liệu kỹ thuật:
...

Sheet PYC5_LienDongCoTai
A1: CỘNG HÒA XÃ HỘI CHỦ NGHĨA VIỆT NAM
A2: Độc lập - Tự do - Hạnh phúc
A3: --------o0o--------
A4: ="Hà Nội, "&IF(LEN(DanhMuc!$E$13)=10,"ngày "&LEFT(DanhMuc!$E$13,2)&" tháng "&MID(DanhMuc!$E$13,4,2)&" năm "&RIGHT(DanhMuc!$E$13,4),"ngày …... tháng …... năm 2026")&"."
A5: PHIẾU YÊU CẦU NGHIỆM THU
A6: =UPPER(SUBSTITUTE(DanhMuc!$C$13,"Phiếu yêu cầu nghiệm thu ",""))
A7: ="SỐ: "&DanhMuc!$D$13
A8: ="Dự án : "&DuAn
A9: ="Gói thầu : "&GoiThau
A10: ="Hạng mục : "&HangMuc
A11: ="Địa điểm : "&DiaDiem
A12: ="Bên A (Bên Mua) : "&BenA_Ten&" - "&BenA_DiaChi
A13: ="Bên B (Bên Bán) : "&BenB_Ten&" - "&BenB_DiaChi
A14: Đối tượng yêu cầu nghiệm thu:
A15: Thang máy P3 và các thiết bị, phụ kiện đi kèm
A16: ="Hợp đồng mua bán số "&SoHD&" ký ngày "&NgayHD&" và "&"Phụ lục Hợp đồng số "&SoPL&" ký ngày "&NgayPL&"."
A17: ="Biên bản phê duyệt vật liệu, sản phẩm xây dựng/Biên bản phê duyệt thiết bị số: 1/TM/BBNTVL-TB/"&MaDA&" ngày "&NgayBBVT&"."
A18: Khối lượng đề nghị nghiệm thu:
A19: TT | B19: Loại vật liệu, sản phẩm | D19: Số lượng | E19: Quy cách | F19: Chủng loại | H19: Giấy xuất xưởng, số lô (CO, CQ) | J19: Nhà sản xuất
A20: 1 | B20: Thang máy P3 và các thiết bị, phụ kiện đi kèm | D20: 1 | E20: Bộ | F20: Thang máy chở khách, PCCC, có Phòng máy | H20: =COCQ | J20: =NhaSX
A21: Đại diện Bên B (Bên Bán):
A22: ="Ông: "&BenB_PL&" Chức vụ: "&BenB_PL_CV&" Chữ ký: ….........................."
A23: Sau khi kiểm tra hồ sơ và quy trình lắp đặt, chạy thử; đối chiếu với bản vẽ thiết kế và các tiêu chuẩn được áp dụng; đối chiếu Hợp đồng, hồ sơ thiết kế, chỉ dẫn kỹ thuật và các quy chuẩn, tiêu chuẩn được áp dụng, chúng tôi đã hoàn thành nghiệm thu nội bộ và khẳng định rằng: Chất lượng Công việc chạy thử đảm bảo các yêu cầu kỹ thuật và đủ điều kiện nghiệm thu.
A24: ="Đề nghị Bên A (Bên Mua) - "&BenA_Ten&" tổ chức nghiệm thu:"
A25: ="Thời gian nghiệm thu: "&IF(DanhMuc!$F$13="","10h00",DanhMuc!$F$13)&" "&IF(LEN(DanhMuc!$H$13)=10,"Ngày "&LEFT(DanhMuc!$H$13,2)&" Tháng "&MID(DanhMuc!$H$13,4,2)&" Năm "&RIGHT(DanhMuc!$H$13,4),"Ngày …. Tháng …... Năm ….....")
A26: Tài liệu kèm theo:
A27: - Biên bản giao hàng;
A28: - Chứng chỉ chất lượng sản phẩm;
A29: - Kết quả thí nghiệm vật liệu;
A30: ="- Dự thảo Biên bản nghiệm thu chạy thử liên động có tải số "&DanhMuc!$D$14&" kèm Bảng kiểm tra (Checklist)."
A31: ="ĐẠI DIỆN BÊN A ("&UPPER(BenA_Ten)&")" | D31: Đã nhận Phiếu yêu cầu lúc 10h20 Ngày …. Tháng …... Năm …..... | H31: Người nhận

Sheet BB5_LienDongCoTai
A2: CỘNG HÒA XÃ HỘI CHỦ NGHĨA VIỆT NAM
A3: Độc lập - Tự do - Hạnh phúc
A4: --------o0o--------
A5: ="Hà Nội, "&IF(LEN(DanhMuc!$E$14)=10,"ngày "&LEFT(DanhMuc!$E$14,2)&" tháng "&MID(DanhMuc!$E$14,4,2)&" năm "&RIGHT(DanhMuc!$E$14,4),"ngày …... tháng …... năm 2026")
A6: =UPPER(DanhMuc!$C$14)
A7: ="SỐ: "&DanhMuc!$D$14
A8: ="Dự án: "&DuAn
A9: ="Gói thầu: "&GoiThau
A10: ="Hạng mục: "&HangMuc
A11: ="Địa điểm: "&DiaDiem
A12: 1. Đối tượng nghiệm thu:
A13: Thang máy P3 (thang máy chở người/PCCC có phòng máy, Schindler) - Chạy thử liên động có tải với các hệ thống liên quan của tòa nhà (báo cháy/PCCC, nguồn điện dự phòng, BMS).
A14: 2. Thành phần nghiệm thu:
A15: ="- Đại diện Bên A (Bên Mua): "&BenA_Ten
A16: =" Ông/Bà: "&IF(BenA_PL="","…......................................",BenA_PL)&" Chức vụ: "&IF(BenA_PL_CV="","…....................",BenA_PL_CV)
A17: ="- Đại diện Bên B (Bên Bán): "&BenB_Ten
A18: =" Ông/Bà: "&IF(BenB_PL="","…......................................",BenB_PL)&" Chức vụ: "&IF(BenB_PL_CV="","…....................",BenB_PL_CV)
A19: 3. Thời gian và địa điểm nghiệm thu:
A20: ="- Bắt đầu: "&IF(DanhMuc!$F$14="","…....... giờ …....... phút",DanhMuc!$F$14)&", "&IF(LEN(DanhMuc!$H$14)=10,"ngày "&LEFT(DanhMuc!$H$14,2)&" tháng "&MID(DanhMuc!$H$14,4,2)&" năm "&RIGHT(DanhMuc!$H$14,4),"ngày …....... tháng …....... năm 2026")
A21: ="- Kết thúc: "&IF(DanhMuc!$G$14="","…....... giờ …....... phút",DanhMuc!$G$14)&", "&IF(LEN(DanhMuc!$H$14)=10,"ngày "&LEFT(DanhMuc!$H$14,2)&" tháng "&MID(DanhMuc!$H$14,4,2)&" năm "&RIGHT(DanhMuc!$H$14,4),"ngày …....... tháng …....... năm 2026")
A22: - Tại: Công trường Tòa nhà Trung tâm Điều hành, Khu Trung tâm ĐHQG Hà Nội, xã Hòa Lạc, Hà Nội
A23: 4. Căn cứ nghiệm thu:
A24: a) Tài liệu pháp lý và hợp đồng:
A25: ="- Hợp đồng mua bán số "&SoHD&" ký ngày "&NgayHD&" giữa "&BenA_Ten&" (Bên A) và "&BenB_Ten&" (Bên B)."
A26: ="- "&"Phụ lục Hợp đồng số "&SoPL&" ký ngày "&NgayPL&" của Hợp đồng số "&SoHD&"."
A27: - Hồ sơ thiết kế, bản vẽ thi công thang máy được hai Bên phê duyệt.
A28: - Biên bản phê duyệt vật liệu/thiết bị số: ….......
A29: ="- Biên bản nghiệm thu vật tư thiết bị số: 1/TM/BBNTVL-TB/"&MaDA&" ngày "&NgayBBVT&"."
A30: ="- Biên bản nghiệm thu liên động không tải: "&DanhMuc!$D$12
A31: b) Quy chuẩn, tiêu chuẩn áp dụng:
A32: - Nghị định 06/2021/NĐ-CP: Quản lý chất lượng và bảo trì công trình xây dựng;
A33: - Thông tư 10/2021/TT-BXD hướng dẫn thi hành Nghị định 06/2021/NĐ-CP;
A34: - QCVN 02:2019/BLĐTBXH: Quy chuẩn kỹ thuật quốc gia về an toàn lao động đối với thang máy;
A35: - TCVN 6396-20:2017 (EN 81-20:2014): Yêu cầu an toàn về cấu tạo và lắp đặt thang máy chở người;
A36: - TCVN 6396-72:2010 (EN 81-72:2003): Thang máy chữa cháy - yêu cầu an toàn;
A37: - TCVN 170:2007: Kết cấu thép - Gia công, lắp ráp và nghiệm thu;
A38: - Và các tiêu chuẩn liên quan khác.
A39: c) Tài liệu kỹ thuật:
A40: - Nhật ký thi công, nhật ký giám sát và các văn bản liên quan đến đối tượng nghiệm thu.
A41: - Catalogue kỹ thuật và chứng chỉ chất lượng của nhà sản xuất Schindler.
...

Sheet PYC6_HoanThanhHangMuc
A1: CỘNG HÒA XÃ HỘI CHỦ NGHĨA VIỆT NAM
A2: Độc lập - Tự do - Hạnh phúc
A3: --------o0o--------
A4: ="Hà Nội, "&IF(LEN(DanhMuc!$E$15)=10,"ngày "&LEFT(DanhMuc!$E$15,2)&" tháng "&MID(DanhMuc!$E$15,4,2)&" năm "&RIGHT(DanhMuc!$E$15,4),"ngày …... tháng …... năm 2026")&"."
A5: PHIẾU YÊU CẦU NGHIỆM THU
A6: =UPPER(SUBSTITUTE(DanhMuc!$C$15,"Phiếu yêu cầu nghiệm thu ",""))
A7: ="SỐ: "&DanhMuc!$D$15
A8: ="Dự án : "&DuAn
A9: ="Gói thầu : "&GoiThau
A10: ="Hạng mục : "&HangMuc
A11: ="Địa điểm : "&DiaDiem
A12: ="Bên A (Bên Mua) : "&BenA_Ten&" - "&BenA_DiaChi
A13: ="Bên B (Bên Bán) : "&BenB_Ten&" - "&BenB_DiaChi
A14: Đối tượng yêu cầu nghiệm thu:
A15: Thang máy P3 và các thiết bị, phụ kiện đi kèm
A16: ="Hợp đồng mua bán số "&SoHD&" ký ngày "&NgayHD&" và "&"Phụ lục Hợp đồng số "&SoPL&" ký ngày "&NgayPL&"."
A17: ="Biên bản phê duyệt vật liệu, sản phẩm xây dựng/Biên bản phê duyệt thiết bị số: 1/TM/BBNTVL-TB/"&MaDA&" ngày "&NgayBBVT&"."
A18: Khối lượng đề nghị nghiệm thu:
A19: TT | B19: Loại vật liệu, sản phẩm | D19: Số lượng | E19: Quy cách | F19: Chủng loại | H19: Giấy xuất xưởng, số lô (CO, CQ) | J19: Nhà sản xuất
A20: 1 | B20: Thang máy P3 và các thiết bị, phụ kiện đi kèm | D20: 1 | E20: Bộ | F20: Thang máy chở khách, PCCC, có Phòng máy | H20: =COCQ | J20: =NhaSX
A21: Đại diện Bên B (Bên Bán):
A22: ="Ông: "&BenB_PL&" Chức vụ: "&BenB_PL_CV&" Chữ ký: ….........................."
A23: Sau khi kiểm tra hồ sơ và quy trình lắp đặt, chạy thử; đối chiếu với bản vẽ thiết kế và các tiêu chuẩn được áp dụng; đối chiếu Hợp đồng, hồ sơ thiết kế, chỉ dẫn kỹ thuật và các quy chuẩn, tiêu chuẩn được áp dụng, chúng tôi đã hoàn thành nghiệm thu nội bộ và khẳng định rằng: Chất lượng Công việc thi công, chạy thử đảm bảo các yêu cầu kỹ thuật và đủ điều kiện nghiệm thu Hoàn thành hạng mục, bàn giao đưa vào sử dụng.
A24: ="Đề nghị Bên A (Bên Mua) - "&BenA_Ten&" tổ chức nghiệm thu:"
A25: ="Thời gian nghiệm thu: "&IF(DanhMuc!$F$15="","10h00",DanhMuc!$F$15)&" "&IF(LEN(DanhMuc!$H$15)=10,"Ngày "&LEFT(DanhMuc!$H$15,2)&" Tháng "&MID(DanhMuc!$H$15,4,2)&" Năm "&RIGHT(DanhMuc!$H$15,4),"Ngày …. Tháng …... Năm ….....")
A26: Tài liệu kèm theo:
A27: - Biên bản giao hàng;
A28: - Chứng chỉ chất lượng sản phẩm;
A29: - Kết quả thí nghiệm vật liệu;
A30: ="- Dự thảo Biên bản nghiệm thu hoàn thành hạng mục đưa vào sử dụng số "&DanhMuc!$D$16&" kèm Bảng kiểm tra (Checklist)."
A31: ="ĐẠI DIỆN BÊN A ("&UPPER(BenA_Ten)&")" | D31: Đã nhận Phiếu yêu cầu lúc 10h20 Ngày …. Tháng …... Năm …..... | H31: Người nhận

Sheet BB6_HoanThanhHangMuc
A2: CỘNG HÒA XÃ HỘI CHỦ NGHĨA VIỆT NAM
A3: Độc lập - Tự do - Hạnh phúc
A4: --------o0o--------
A5: ="Hà Nội, "&IF(LEN(DanhMuc!$E$16)=10,"ngày "&LEFT(DanhMuc!$E$16,2)&" tháng "&MID(DanhMuc!$E$16,4,2)&" năm "&RIGHT(DanhMuc!$E$16,4),"ngày …... tháng …... năm 2026")
A6: =UPPER(DanhMuc!$C$16)
A7: ="SỐ: "&DanhMuc!$D$16
A8: ="Dự án: "&DuAn
A9: ="Gói thầu: "&GoiThau
A10: ="Hạng mục: "&HangMuc
A11: ="Địa điểm: "&DiaDiem
A12: 1. Đối tượng nghiệm thu:
A13: Hoàn thành hạng mục Cung cấp và lắp đặt Thang máy P3 (thang máy chở người/PCCC có phòng máy, Schindler) tại Tòa nhà Trung tâm Điều hành - ĐHQG Hà Nội.
A14: 2. Thành phần nghiệm thu:
A15: ="- Đại diện Bên A (Bên Mua): "&BenA_Ten
A16: =" Ông/Bà: "&IF(BenA_PL="","…......................................",BenA_PL)&" Chức vụ: "&IF(BenA_PL_CV="","…....................",BenA_PL_CV)
A17: ="- Đại diện Bên B (Bên Bán): "&BenB_Ten
A18: =" Ông/Bà: "&IF(BenB_PL="","…......................................",BenB_PL)&" Chức vụ: "&IF(BenB_PL_CV="","…....................",BenB_PL_CV)
A19: 3. Thời gian và địa điểm nghiệm thu:
A20: ="- Bắt đầu: "&IF(DanhMuc!$F$16="","…....... giờ …....... phút",DanhMuc!$F$16)&", "&IF(LEN(DanhMuc!$H$16)=10,"ngày "&LEFT(DanhMuc!$H$16,2)&" tháng "&MID(DanhMuc!$H$16,4,2)&" năm "&RIGHT(DanhMuc!$H$16,4),"ngày …....... tháng …....... năm 2026")
A21: ="- Kết thúc: "&IF(DanhMuc!$G$16="","…....... giờ …....... phút",DanhMuc!$G$16)&", "&IF(LEN(DanhMuc!$H$16)=10,"ngày "&LEFT(DanhMuc!$H$16,2)&" tháng "&MID(DanhMuc!$H$16,4,2)&" năm "&RIGHT(DanhMuc!$H$16,4),"ngày …....... tháng …....... năm 2026")
A22: - Tại: Công trường Tòa nhà Trung tâm Điều hành, Khu Trung tâm ĐHQG Hà Nội, xã Hòa Lạc, Hà Nội
A23: 4. Căn cứ nghiệm thu:
A24: a) Tài liệu pháp lý và hợp đồng:
A25: ="- Hợp đồng mua bán số "&SoHD&" ký ngày "&NgayHD&" giữa "&BenA_Ten&" (Bên A) và "&BenB_Ten&" (Bên B)."
A26: ="- "&"Phụ lục Hợp đồng số "&SoPL&" ký ngày "&NgayPL&" của Hợp đồng số "&SoHD&"."
A27: - Hồ sơ thiết kế, bản vẽ thi công thang máy được hai Bên phê duyệt.
A28: - Biên bản phê duyệt vật liệu/thiết bị số: ….......
A29: ="- Biên bản nghiệm thu vật tư thiết bị số: 1/TM/BBNTVL-TB/"&MaDA&" ngày "&NgayBBVT&"."
A30: ="- BB lắp đặt tĩnh: "&DanhMuc!$D$6
A31: ="- BB đơn động không tải: "&DanhMuc!$D$8
A32: ="- BB đơn động có tải: "&DanhMuc!$D$10
A33: ="- BB liên động không tải: "&DanhMuc!$D$12
A34: ="- BB liên động có tải: "&DanhMuc!$D$14
A35: - Giấy chứng nhận kiểm định kỹ thuật an toàn thang máy P3 (Cơ quan kiểm định được chỉ định).
A36: b) Quy chuẩn, tiêu chuẩn áp dụng:
A37: - Nghị định 06/2021/NĐ-CP: Quản lý chất lượng và bảo trì công trình xây dựng;
A38: - Thông tư 10/2021/TT-BXD hướng dẫn thi hành Nghị định 06/2021/NĐ-CP;
A39: - QCVN 02:2019/BLĐTBXH: Quy chuẩn kỹ thuật quốc gia về an toàn lao động đối với thang máy;
A40: - TCVN 6396-20:2017 (EN 81-20:2014): Yêu cầu an toàn về cấu tạo và lắp đặt thang máy chở người;
A41: - TCVN 6396-72:2010 (EN 81-72:2003): Thang máy chữa cháy - yêu cầu an toàn;
...

Sheet BBG_BanGiao
A2: CỘNG HÒA XÃ HỘI CHỦ NGHĨA VIỆT NAM
A3: Độc lập - Tự do - Hạnh phúc
A4: --------o0o--------
A6: ="Hà Nội, "&IF(LEN(DanhMuc!$E$17)=10,"ngày "&LEFT(DanhMuc!$E$17,2)&" tháng "&MID(DanhMuc!$E$17,4,2)&" năm "&RIGHT(DanhMuc!$E$17,4),"ngày …... tháng …... năm 2026")
A7: =UPPER(DanhMuc!$C$17)
A8: LIFT HANDOVER CERTIFICATE
A10: Công trình: Project: Số hợp đồng: Contract no: | C10: ="TÒA NHÀ TRUNG TÂM ĐIỀU HÀNH – Khu trung tâm ĐHQGHN Hợp đồng mua bán số "&SoHD&" ký ngày "&NgayHD&" và "&"Phụ lục Hợp đồng số "&SoPL&" ký ngày "&NgayPL
A12: Bên Mua | D12: : | E12: =BenA_Ten&" Địa chỉ: "&BenA_DiaChi
A13: Buyer | E13: ="Đại diện Ông "&BenA_PL&" – "&BenA_PL_CV
A15: Bên Bán | D15: : | E15: =BenB_Ten
A16: Seller | E16: ="Địa chỉ: "&BenB_DiaChi
E17: ="Đại diện: Ông "&BenB_PL&" – "&BenB_PL_CV
A18: Bên Mua và Bên bán thống nhất ký kết Biên bản bàn giao thang máy (sau đây gọi là "Biên bản bàn giao") theo các nội dung sau đây:
A19: The Buyer and the Seller unanimously agree to enter the Lift hand-over Certificate (hereinafter referred as the “Certificate”) with the following provisions:
A20: Tên thiết bị bàn giao: Thang máy Schindler 6000 mã hiệu thang máy số P3
A21: Equipment will be handed over: Schindler 6000 No. P3
A22: Số lượng: 01
A23: Quantity: 01
A24: Các thông số kỹ thuật chính:
A25: Main Technical Spectification:
A26: * Chủng loại / Model | G26: : | H26: Schindler 6000
A27: * Số điểm dừng / No. of Stop | G27: : | H27: 12
A28: * Vận tốc (m/s) / Speed (m/s) | G28: : | H28: 1.75
A29: * Tải trọng (Kg) / Capacity (kg) | G29: : | H29: 1000
A30: Biên bản bào giao này xác nhận thang máy trên đã được lắp đặt hoàn chỉnh, đã được kiểm định an toàn lần đầu bởi cơ quan chức năng có thẩm quyền theo quy định kiểm định an toàn của Nhà Nước (Theo Giấy chứng nhận Kết quả Kiểm định cho Thang máy số ........ ngày .... tháng ... năm 202...).
A31: Trong quá trình sử dụng thang máy, Bên mua phải có trách nhiệm bảo quản và hoàn toàn chịu trách nhiệm với các lỗi của người sử dụng gây ra như: nước tràn vào thang máy, chèn/chặn hay va đập làm móp méo/cong vênh/xước cửa tầng, Cabin thang máy hoặc cháy chập nguồn điện cung cấp, hư hỏng các thiết bị của thang máy do người sử dụng, v.v…
A32: During the use of the lift, the Buyer must be responsible for preserving and being fully responsible for the user's errors, such as water overflowing into the lift, insertion /blocking or impact distorting /curving /scratching the door, or short- circuiting the power supply, and damage to lift equipment caused by users....
A33: Biên bản này được lập thành 2 (hai) bản, mỗi bên giữ 1 (một) bản. Tiếng Việt sẽ được ưu tiên áp dụng để diễn giải.
A34: This Certificate is written in 2 (Two) copies, each party keeps 1 (One) copy. Vietnamese version shall prevail to be used for the purpose of interpretation.
A35: *Thời gian bảo hành, bảo trì miễn phí: theo điều 7 của Hợp đồng – …... tháng kể từ ngày Phát hành _________________________ – từ ngày …./...../202... cho đến hết ngày …./...../202…
A36: Warranty and free maintainance period: follow the contrac ternm 7
A37: ĐẠI DIỆN BÊN MUA/ On behalf of the Buyer | F37: ĐẠI DIỆN BÊN BÁN/ On behalf of the Seller
